<?xml version="1.0"?>
<sdf version="1.8">
  <model name="inspectorbot">
    <static>false</static>
    <self_collide>false</self_collide>
    
    <!-- Base chassis -->
    <link name="base_link">
      <pose>0 0 0 0 0 0</pose>
      <inertial>
        <mass>2.0</mass>
        <inertia>
          <ixx>0.1</ixx>
          <ixy>0</ixy>
          <ixz>0</ixz>
          <iyy>0.1</iyy>
          <iyz>0</iyz>
          <izz>0.1</izz>
        </inertia>
      </inertial>
      
      <collision name="base_collision">
        <geometry>
          <box>
            <size>0.5 0.5 0.2</size>
          </box>
        </geometry>
      </collision>
      
      <visual name="base_visual">
        <!-- Referencing meshes by package API requires setting GZ_SIM_RESOURCE_PATH to the install directory-->
        <geometry>
          <mesh>
            <uri>package://models/inspectorbot/meshes/base_link.stl</uri>
            <scale>0.001 0.001 0.001</scale>
          </mesh>
        </geometry>
        <material>
          <ambient>1.0 1.0 1.0 1.0</ambient>
          <diffuse>1.0 1.0 1.0 1.0</diffuse>
        </material>
      </visual>
    </link>

    <!-- Front Left Propeller -->
    <link name="front_left_prop">
      <pose>0.25 0.25 0.1 0 0 0</pose>
      <inertial>
        <mass>0.1</mass>
        <inertia>
          <ixx>0.001</ixx>
          <ixy>0</ixy>
          <ixz>0</ixz>
          <iyy>0.001</iyy>
          <iyz>0</iyz>
          <izz>0.002</izz>
        </inertia>
      </inertial>
      
      <collision name="prop_collision">
        <geometry>
          <cylinder>
            <radius>0.05</radius>
            <length>0.01</length>
          </cylinder>
        </geometry>
      </collision>
      
      <visual name="prop_visual">
        <!-- Referencing meshes by package API requires setting GZ_SIM_RESOURCE_PATH to the install directory-->
        <geometry>
          <mesh>
            <uri>package://models/inspectorbot/meshes/propeller.stl</uri>
            <scale>0.001 0.001 0.001</scale>
          </mesh>
        </geometry>
        <material>
          <ambient>0.1 0.1 0.1 1.0</ambient>
          <diffuse>0.1 0.1 0.1 1.0</diffuse>
        </material>
      </visual>
    </link>

    <!-- Front Right Propeller -->
    <link name="front_right_prop">
      <pose>0.25 -0.25 0.1 0 0 0</pose>
      <inertial>
        <mass>0.1</mass>
        <inertia>
          <ixx>0.001</ixx>
          <ixy>0</ixy>
          <ixz>0</ixz>
          <iyy>0.001</iyy>
          <iyz>0</iyz>
          <izz>0.002</izz>
        </inertia>
      </inertial>
      
      <collision name="prop_collision">
        <geometry>
          <cylinder>
            <radius>0.05</radius>
            <length>0.01</length>
          </cylinder>
        </geometry>
      </collision>
      
      <visual name="prop_visual">
        <!-- Referencing meshes by package API requires setting GZ_SIM_RESOURCE_PATH to the install directory-->
        <geometry>
          <mesh>
            <uri>package://models/inspectorbot/meshes/propeller.stl</uri>
            <scale>0.001 0.001 0.001</scale>
          </mesh>
        </geometry>
        <material>
          <ambient>0.1 0.1 0.1 1.0</ambient>
          <diffuse>0.1 0.1 0.1 1.0</diffuse>
        </material>
      </visual>
    </link>

    <!-- Rear Left Propeller -->
    <link name="rear_left_prop">
      <pose>-0.25 0.25 0.1 0 0 0</pose>
      <inertial>
        <mass>0.1</mass>
        <inertia>
          <ixx>0.001</ixx>
          <ixy>0</ixy>
          <ixz>0</ixz>
          <iyy>0.001</iyy>
          <iyz>0</iyz>
          <izz>0.002</izz>
        </inertia>
      </inertial>
      
      <collision name="prop_collision">
        <geometry>
          <cylinder>
            <radius>0.05</radius>
            <length>0.01</length>
          </cylinder>
        </geometry>
      </collision>
      
      <visual name="prop_visual">
        <!-- Referencing meshes by package API requires setting GZ_SIM_RESOURCE_PATH to the install directory-->
        <geometry>
          <mesh>
            <uri>package://models/inspectorbot/meshes/propeller.stl</uri>
            <scale>0.001 0.001 0.001</scale>
          </mesh>
        </geometry>
        <material>
          <ambient>0.1 0.1 0.1 1.0</ambient>
          <diffuse>0.1 0.1 0.1 1.0</diffuse>
        </material>
      </visual>
    </link>

    <!-- Rear Right Propeller -->
    <link name="rear_right_prop">
      <pose>-0.25 -0.25 0.1 0 0 0</pose>
      <inertial>
        <mass>0.1</mass>
        <inertia>
          <ixx>0.001</ixx>
          <ixy>0</ixy>
          <ixz>0</ixz>
          <iyy>0.001</iyy>
          <iyz>0</iyz>
          <izz>0.002</izz>
        </inertia>
      </inertial>
      
      <collision name="prop_collision">
        <geometry>
          <cylinder>
            <radius>0.05</radius>
            <length>0.01</length>
          </cylinder>
        </geometry>
      </collision>
      
      <visual name="prop_visual">
        <!-- Referencing meshes by package API requires setting GZ_SIM_RESOURCE_PATH to the install directory-->
        <geometry>
          <mesh>
            <uri>package://models/inspectorbot/meshes/propeller.stl</uri>
            <scale>0.001 0.001 0.001</scale>
          </mesh>
        </geometry>
        <material>
          <ambient>0.1 0.1 0.1 1.0</ambient>
          <diffuse>0.1 0.1 0.1 1.0</diffuse>
        </material>
      </visual>
    </link>

    <!-- Camera Link -->
    <link name="camera_link">
      <pose>0.25 0 0.15 0 0 0</pose>
      <inertial>
        <mass>0.01</mass>
        <inertia>
          <ixx>0.00001</ixx>
          <ixy>0</ixy>
          <ixz>0</ixz>
          <iyy>0.00001</iyy>
          <iyz>0</iyz>
          <izz>0.00001</izz>
        </inertia>
      </inertial>
      
      <collision name="camera_collision">
        <geometry>
          <box>
            <size>0.05 0.05 0.05</size>
          </box>
        </geometry>
      </collision>
      
      <visual name="camera_visual">
        <geometry>
          <box>
            <size>0.05 0.05 0.05</size>
          </box>
        </geometry>
        <material>
          <ambient>0.0 0.0 1.0 1.0</ambient>
          <diffuse>0.0 0.0 1.0 1.0</diffuse>
        </material>
      </visual>
      
      <!-- Camera sensor -->
      <sensor name="camera" type="camera">
        <always_on>true</always_on>
        <update_rate>30</update_rate>
        <visualize>true</visualize>
        <camera>
          <horizontal_fov>1.047</horizontal_fov>
          <image>
            <width>1280</width>
            <height>720</height>
            <format>R8G8B8</format>
          </image>
          <clip>
            <near>0.1</near>
            <far>100</far>
          </clip>
          <noise>
            <type>gaussian</type>
            <mean>0.0</mean>
            <stddev>0.007</stddev>
          </noise>
        </camera>
      </sensor>
    </link>

    <!-- GPS Link -->
    <link name="gps_link">
      <pose>0 0 0.25 0 0 0</pose>
      <inertial>
        <mass>0.01</mass>
        <inertia>
          <ixx>0.00001</ixx>
          <ixy>0</ixy>
          <ixz>0</ixz>
          <iyy>0.00001</iyy>
          <iyz>0</iyz>
          <izz>0.00001</izz>
        </inertia>
      </inertial>
      
      <collision name="gps_collision">
        <geometry>
          <box>
            <size>0.05 0.05 0.05</size>
          </box>
        </geometry>
      </collision>
      
      <visual name="gps_visual">
        <geometry>
          <box>
            <size>0.05 0.05 0.05</size>
          </box>
        </geometry>
        <material>
          <ambient>0.0 1.0 0.0 1.0</ambient>
          <diffuse>0.0 1.0 0.0 1.0</diffuse>
        </material>
      </visual>
      
      <!-- GPS/NavSat sensor -->
      <sensor name="navsat" type="navsat">
        <always_on>true</always_on>
        <update_rate>10</update_rate>
        <navsat>
          <position_sensing>
            <horizontal>
              <noise type="gaussian">
                <mean>0.0</mean>
                <stddev>0.0002</stddev>
              </noise>
            </horizontal>
            <vertical>
              <noise type="gaussian">
                <mean>0.0</mean>
                <stddev>0.0002</stddev>
              </noise>
            </vertical>
          </position_sensing>
          <velocity_sensing>
            <horizontal>
              <noise type="gaussian">
                <mean>0.0</mean>
                <stddev>0.002</stddev>
              </noise>
            </horizontal>
            <vertical>
              <noise type="gaussian">
                <mean>0.0</mean>
                <stddev>0.002</stddev>
              </noise>
            </vertical>
          </velocity_sensing>
        </navsat>
      </sensor>
    </link>

    <!-- IMU Link -->
    <link name="imu_link">
      <pose>0 0 0.15 0 0 0</pose>
      <inertial>
        <mass>0.01</mass>
        <inertia>
          <ixx>0.00001</ixx>
          <ixy>0</ixy>
          <ixz>0</ixz>
          <iyy>0.00001</iyy>
          <iyz>0</iyz>
          <izz>0.00001</izz>
        </inertia>
      </inertial>
      
      <collision name="imu_collision">
        <geometry>
          <box>
            <size>0.03 0.03 0.03</size>
          </box>
        </geometry>
      </collision>
      
      <visual name="imu_visual">
        <geometry>
          <box>
            <size>0.03 0.03 0.03</size>
          </box>
        </geometry>
        <material>
          <ambient>1.0 0.0 0.0 1.0</ambient>
          <diffuse>1.0 0.0 0.0 1.0</diffuse>
        </material>
      </visual>
      
      <!-- IMU sensor -->
      <sensor name="imu" type="imu">
        <always_on>true</always_on>
        <update_rate>100</update_rate>
        <imu>
          <angular_velocity>
            <x>
              <noise type="gaussian">
                <mean>0.0</mean>
                <stddev>0.0002</stddev>
              </noise>
            </x>
            <y>
              <noise type="gaussian">
                <mean>0.0</mean>
                <stddev>0.0002</stddev>
              </noise>
            </y>
            <z>
              <noise type="gaussian">
                <mean>0.0</mean>
                <stddev>0.0002</stddev>
              </noise>
            </z>
          </angular_velocity>
          <linear_acceleration>
            <x>
              <noise type="gaussian">
                <mean>0.0</mean>
                <stddev>0.017</stddev>
              </noise>
            </x>
            <y>
              <noise type="gaussian">
                <mean>0.0</mean>
                <stddev>0.017</stddev>
              </noise>
            </y>
            <z>
              <noise type="gaussian">
                <mean>0.0</mean>
                <stddev>0.017</stddev>
              </noise>
            </z>
          </linear_acceleration>
        </imu>
      </sensor>
    </link>

    <!-- Joints -->
    <joint name="front_left_prop_joint" type="revolute">
      <parent>base_link</parent>
      <child>front_left_prop</child>
      <axis>
        <xyz>0 0 1</xyz>
        <limit>
          <lower>-1e16</lower>
          <upper>1e16</upper>
        </limit>
      </axis>
    </joint>

    <joint name="front_right_prop_joint" type="revolute">
      <parent>base_link</parent>
      <child>front_right_prop</child>
      <axis>
        <xyz>0 0 1</xyz>
        <limit>
          <lower>-1e16</lower>
          <upper>1e16</upper>
        </limit>
      </axis>
    </joint>

    <joint name="rear_left_prop_joint" type="revolute">
      <parent>base_link</parent>
      <child>rear_left_prop</child>
      <axis>
        <xyz>0 0 1</xyz>
        <limit>
          <lower>-1e16</lower>
          <upper>1e16</upper>
        </limit>
      </axis>
    </joint>

    <joint name="rear_right_prop_joint" type="revolute">
      <parent>base_link</parent>
      <child>rear_right_prop</child>
      <axis>
        <xyz>0 0 1</xyz>
        <limit>
          <lower>-1e16</lower>
          <upper>1e16</upper>
        </limit>
      </axis>
    </joint>

    <joint name="camera_joint" type="fixed">
      <parent>base_link</parent>
      <child>camera_link</child>
    </joint>

    <joint name="gps_joint" type="fixed">
      <parent>base_link</parent>
      <child>gps_link</child>
    </joint>

    <joint name="imu_joint" type="fixed">
      <parent>base_link</parent>
      <child>imu_link</child>
    </joint>

    <!-- Multicopter Control Plugin -->
    <plugin filename="libgz-sim-multicopter-motor-model-system.so"
            name="gz::sim::systems::MulticopterMotorModel">
      <robotNamespace>inspectorbot</robotNamespace>
      <jointName>front_left_prop_joint</jointName>
      <linkName>front_left_prop</linkName>
      <turningDirection>ccw</turningDirection>
      <timeConstantUp>0.0125</timeConstantUp>
      <timeConstantDown>0.025</timeConstantDown>
      <maxRotVelocity>1100</maxRotVelocity>
      <motorConstant>5.84e-06</motorConstant>
      <momentConstant>0.06</momentConstant>
      <commandSubTopic>command/motor_speed</commandSubTopic>
      <motorNumber>0</motorNumber>
      <rotorDragCoefficient>0.000175</rotorDragCoefficient>
      <rollingMomentCoefficient>1e-06</rollingMomentCoefficient>
      <motorSpeedPubTopic>motor_speed/0</motorSpeedPubTopic>
      <rotorVelocitySlowdownSim>10</rotorVelocitySlowdownSim>
    </plugin>

    <plugin filename="libgz-sim-multicopter-motor-model-system.so"
            name="gz::sim::systems::MulticopterMotorModel">
      <robotNamespace>inspectorbot</robotNamespace>
      <jointName>front_right_prop_joint</jointName>
      <linkName>front_right_prop</linkName>
      <turningDirection>cw</turningDirection>
      <timeConstantUp>0.0125</timeConstantUp>
      <timeConstantDown>0.025</timeConstantDown>
      <maxRotVelocity>1100</maxRotVelocity>
      <motorConstant>5.84e-06</motorConstant>
      <momentConstant>0.06</momentConstant>
      <commandSubTopic>command/motor_speed</commandSubTopic>
      <motorNumber>1</motorNumber>
      <rotorDragCoefficient>0.000175</rotorDragCoefficient>
      <rollingMomentCoefficient>1e-06</rollingMomentCoefficient>
      <motorSpeedPubTopic>motor_speed/1</motorSpeedPubTopic>
      <rotorVelocitySlowdownSim>10</rotorVelocitySlowdownSim>
    </plugin>

    <plugin filename="libgz-sim-multicopter-motor-model-system.so"
            name="gz::sim::systems::MulticopterMotorModel">
      <robotNamespace>inspectorbot</robotNamespace>
      <jointName>rear_left_prop_joint</jointName>
      <linkName>rear_left_prop</linkName>
      <turningDirection>cw</turningDirection>
      <timeConstantUp>0.0125</timeConstantUp>
      <timeConstantDown>0.025</timeConstantDown>
      <maxRotVelocity>1100</maxRotVelocity>
      <motorConstant>5.84e-06</motorConstant>
      <momentConstant>0.06</momentConstant>
      <commandSubTopic>command/motor_speed</commandSubTopic>
      <motorNumber>2</motorNumber>
      <rotorDragCoefficient>0.000175</rotorDragCoefficient>
      <rollingMomentCoefficient>1e-06</rollingMomentCoefficient>
      <motorSpeedPubTopic>motor_speed/2</motorSpeedPubTopic>
      <rotorVelocitySlowdownSim>10</rotorVelocitySlowdownSim>
    </plugin>

    <plugin filename="libgz-sim-multicopter-motor-model-system.so"
            name="gz::sim::systems::MulticopterMotorModel">
      <robotNamespace>inspectorbot</robotNamespace>
      <jointName>rear_right_prop_joint</jointName>
      <linkName>rear_right_prop</linkName>
      <turningDirection>ccw</turningDirection>
      <timeConstantUp>0.0125</timeConstantUp>
      <timeConstantDown>0.025</timeConstantDown>
      <maxRotVelocity>1100</maxRotVelocity>
      <motorConstant>5.84e-06</motorConstant>
      <momentConstant>0.06</momentConstant>
      <commandSubTopic>command/motor_speed</commandSubTopic>
      <motorNumber>3</motorNumber>
      <rotorDragCoefficient>0.000175</rotorDragCoefficient>
      <rollingMomentCoefficient>1e-06</rollingMomentCoefficient>
      <motorSpeedPubTopic>motor_speed/3</motorSpeedPubTopic>
      <rotorVelocitySlowdownSim>10</rotorVelocitySlowdownSim>
    </plugin>

    <!-- Multicopter Control System -->
    <plugin filename="libgz-sim-multicopter-control-system.so"
            name="gz::sim::systems::MulticopterVelocityControl">
      <robotNamespace>inspectorbot</robotNamespace>
      <commandSubTopic>cmd_vel</commandSubTopic>
      <enableSubTopic>enable</enableSubTopic>
      <comLinkName>base_link</comLinkName>
      <velocityGain>2.5 2.5 2.0</velocityGain>
      <attitudeGain>2.0 2.0 0.6</attitudeGain>
      <angularRateGain>0.4 0.4 0.2</angularRateGain>
      <maximumLinearAcceleration>2 2 2</maximumLinearAcceleration>
      <maximumLinearVelocity>5 5 3</maximumLinearVelocity>
      <maximumAngularVelocity>3 3 3</maximumAngularVelocity>
      <linearVelocityNoiseMean>0 0 0</linearVelocityNoiseMean>
      <linearVelocityNoiseStdDev>0.05 0.05 0.05</linearVelocityNoiseStdDev>
      <angularVelocityNoiseMean>0 0 0</angularVelocityNoiseMean>
      <angularVelocityNoiseStdDev>0.01 0.01 0.01</angularVelocityNoiseStdDev>
      <rotorConfiguration>
        <rotor>
          <jointName>front_left_prop_joint</jointName>
          <forceConstant>5.84e-06</forceConstant>
          <momentConstant>0.06</momentConstant>
          <direction>1</direction>
        </rotor>
        <rotor>
          <jointName>front_right_prop_joint</jointName>
          <forceConstant>5.84e-06</forceConstant>
          <momentConstant>0.06</momentConstant>
          <direction>-1</direction>
        </rotor>
        <rotor>
          <jointName>rear_left_prop_joint</jointName>
          <forceConstant>5.84e-06</forceConstant>
          <momentConstant>0.06</momentConstant>
          <direction>-1</direction>
        </rotor>
        <rotor>
          <jointName>rear_right_prop_joint</jointName>
          <forceConstant>5.84e-06</forceConstant>
          <momentConstant>0.06</momentConstant>
          <direction>1</direction>
        </rotor>
      </rotorConfiguration>
    </plugin>

  </model>
</sdf>
